Workbook

Sheet Bìa
B1: Biên bản nghiệm thu tính năng hệ thống dịch vụ Digital Market Phase 2 - Số hóa CP và gói cước Bundle-
B5: STT | C5: Nội dung | D5: Pass | E5: Fail | F5: Pending | G5: N/A | H5: Untested | I5: Number of test cases | J5: Link TCs
C6: CMS Digital Market
B7: 1 | C7: ATP | D7: =ATP!C2 -> 7 | E7: =ATP!D2 -> 0 | F7: =ATP!E2 -> 0 | G7: =ATP!F2 -> 0 | H7: =ATP!G2 -> 0 | I7: =ATP!H2 -> 7
B8: 2 | C8: API CSP_Phase2 | D8: ='API CSP '!C2 -> 2 | E8: ='API CSP '!D2 -> 0 | F8: =ATP!E2 -> 0 | G8: ='API CSP '!F2 -> 0 | H8: ='API CSP '!G2 -> 1 | I8: ='API CSP '!H2 -> 3
B9: 3 | C9: CMS_Admin_Phase2 | D9: =CMS_admin!C2 -> 381 | E9: =CMS_admin!D2 -> 1 | F9: =CMS_admin!E2 -> 1 | G9: =CMS_admin!F2 -> 0 | H9: =CMS_admin!G2 -> 1 | I9: =CMS_admin!H2 -> 384
B10: 4 | C10: CMS_CP_Phase2 | D10: =CMS_CP!C2 -> 202 | E10: =CMS_CP!D2 -> 0 | F10: =CMS_CP!E2 -> 2 | G10: =CMS_CP!F2 -> 0 | H10: =CMS_CP!G2 -> 0 | I10: =CMS_CP!H2 -> 204
B11: 5 | C11: UAT kịch bản gói | D11: ='UAT kịch bản gói Bundle'!C2 -> 13 | E11: ='UAT kịch bản gói Bundle'!D2 -> 0 | F11: ='UAT kịch bản gói Bundle'!E2 -> 0 | G11: ='UAT kịch bản gói Bundle'!F2 -> 1 | H11: ='UAT kịch bản gói Bundle'!G2 -> 0 | I11: ='UAT kịch bản gói Bundle'!H2 -> 14
B12: 6
B13: 7
B14: 8
B15: 9
C16: Sub total | D16: =SUM(D5:D15) -> 605 | E16: =SUM(E5:E15) -> 1 | F16: =SUM(F5:F15) -> 3 | G16: =SUM(G5:G15) -> 1 | H16: =SUM(H7:H15) -> 2 | I16: =SUM(I5:I15) -> 612
C18: Tỷ lệ bao phủ | E18: =(D16+E16)*100/(I16-G16) -> 99.181669 | F18: %
C19: Tỷ lệ bao phủ thành công | E19: =D16*100/(I16-G16) -> 99.018003 | F19: %
B22: Phòng Phát triển sản phẩm | D22: Phòng Vận hành | G22: Phòng Phát triển kinh doanh
B23: Hồ Thị Thúy Hà Đỗ Thị Hằng | D23: Tô Đình Minh Cường | G23: Bùi Thị Thùy Dương
B30: Ngô Nhật Anh Đồng Tiến Đạt | D30: Trần Phan Anh | G30: Hà Thị Hồng Thái

Sheet ATP
B1: Kết quả | C1: Pass | D1: Fail | E1: Pending | F1: N/A | G1: Untested | H1: Total | I1: Total
C2: =COUNTIF(G4:G1371,"Pass") +countif(G4:G1371,"Accepted") -> 7 | D2: =COUNTIF(G4:G1371,"Fail") -> 0 | E2: =COUNTIF(G4:G1371,"Pending") -> 0 | F2: =COUNTIF(G4:G1371,"N/A") -> 0 | G2: =H2-C2-D2-E2-F2 -> 0 | H2: =COUNTA(E4:E1492) -> 7 | I2: =COUNTA(F4:F1492) -> 7
A3: ID | B3: Tên Test Case | C3: Tiền điều kiện | D3: Các bước thực hiện | E3: Kết quả mong muốn | F3: Kết quả thực tế | G3: Kết quả | H3: Ngày thực hiện | I3: Mức độ ưu tiên | J3: Bug fix status | K3: Fixed by | L3: Ghi chú
A4: I./ | B4: Truy cập CMS Admin
A5: TC_001 | B5: Truy cập trang CMS Admin | D5: Truy cập trang CMS Admin thành công và sử dụng được các tính năng (chi tiết testcase CMS Admin Domain: http://dimarket.vn/digitalMarketing/login | E5: Truy cập trang CMS Admin thành công và sử dụng được các tính năng (chi tiết testcase CMS Admin) | F5: Thành công | G5: Pass
A6: II./ | B6: Truy cập CMS CP
A7: TC_002 | B7: Truy cập trang CMS CP | D7: Truy cập trang CMS Admin thành công và sử dụng được các tính năng (chi tiết testcase CMS CP) Domain: http://dimarket.vn/digitalMarketing_cp/login | E7: Truy cập trang CMS CP thành công và sử dụng được các tính năng (chi tiết testcase CMS CP) | F7: Thành công | G7: Pass
A8: III./ | B8: Tích hợp hệ thống MBG
A9: TC_003 | B9: Tích hợp hệ thống MBG | C9: Khai báo sản phẩm và được duyệt lần 1 trên DMP | D9: Khai báo sản phẩm và được duyệt lần 1 trên DMP | E9: Tích hợp tạo gói thành công sang MBG | F9: 2026-02-27 17:38:31,508 [INFO] (controller.TblProductController):468 - Parameter:: approveSubmit productId=530 2026-02-27 17:38:31,779 [INFO] (service.MbgApiService):175 - Request url: http://10.144.82.231:8088/mbgcmsa/package/create, request: {"request_id":1772188711766,"authen_key":"eyJ0eXAiOiJKV1QiLCJhbGciOiJSUzI1NiJ9.eyJtc2lzZG4iOiI4NDk0NjQ0NjQyNCIsInJlcXVlc3RUaW1lIjoiMTYyMzIyNzIwODUyNSJ9.tYs2iRDm5oexDdgcRIZDfjaZ3HEJh1GBfq_smGGmF1UbWqZTDb61Hj7wP2PcrfeM-cT_IZbxNMdd6bQ36Bk4LyNSWrvdFy8Gj6G7OFcnfC5d9_LPPwnqkW-V2-EnbpDY9tlHbNsEFNiGd602Pk3SPOiVk1MQFAFbmjWdFg4E9Dm4cmq1eq6Qr6CAzRUO3o8jxdFoHGRRmEkN1UMr_X9uzPXGCdsL_CAjVgGHxGFGFMhMyiyy-M6vK5ZMVqgYrnNHvH9PUXGDmkQz7BqmxGBdmo6FyqXwb5rL0i2LaEBlSIR6bEXoSREBXdIR82bO0rTP-gDczs7cN5YryYj0TiWgag","content_pack_code":"PATEST2","content_pack_name":"PATEST2","api_url":"http://10.144.92.2:8080/cpbga","api_sync_url":"http://10.144.92.2:8080/cpbga","description":"test2","allow_auto_renew":1,"allow_postpaid":1,"duration_unit":1,"duraction_cycle":1,"allow_duplicate":0,"price":0,"vascloud_service":"DIGITALMARKET","vascloud_package":"PATEST2","renew_price_tklh":2,"allow_prepaid":1,"allow_ezcom":0,"data_plus":30,"data_plus_code":"DC_MBG2_30MB_1D","csp_code":"CP_MEDIA","service_code":"DIGITALMARKET","retry_number":1,"retry_period":8,"package_type":1,"whitelist":"84915285568, 84845148866","mt_short_code":"1376","charging_option":2,"is_check_data_when_unreg":0,"allow_convert_packages":0,"check_bigdata_consumption":0,"comsumption_or_active_time":0,"renew_tel_30_days":0,"api_status":0,"is_sent_mt3":0,"cp_name":"CP NHATANHTEST-DIGITALMARKET"}, authen: Bearer eyJ0eXAiOiJKV1QiLCJhbGciOiJSUzI1NiJ9.eyJtc2lzZG4iOiI4NDk0NjQ0NjQyNCIsInJlcXVlc3RUaW1lIjoiMTYyMzIyNzIwODUyNSJ9.tYs2iRDm5oexDdgcRIZDfjaZ3HEJh1GBfq_smGGmF1UbWqZTDb61Hj7wP2PcrfeM-cT_IZbxNMdd6bQ36Bk4LyNSWrvdFy8Gj6G7OFcnfC5d9_LPPwnqkW-V2-EnbpDY9tlHbNsEFNiGd602Pk3SPOiVk1MQFAFbmjWdFg4E9Dm4cmq1eq6Qr6CAzRUO3o8jxdFoHGRRmEkN1UMr_X9uzPXGCdsL_CAjVgGHxGFGFMhMyiyy-M6vK5ZMVqgYrnNHvH9PUXGDmkQz7BqmxGBdmo6FyqXwb5rL0i2LaEBlSIR6bEXoSREBXdIR82bO0rTP-gDczs7cN5YryYj0TiWgag 2026-02-27 17:38:31,854 [INFO] (service.MbgApiService):182 - Response url:http://10.144.82.231:8088/mbgcmsa/package/create, request: {"request_id":1772188711766,"authen_key":"eyJ0eXAiOiJKV1QiLCJhbGciOiJSUzI1NiJ9.eyJtc2lzZG4iOiI4NDk0NjQ0NjQyNCIsInJlcXVlc3RUaW1lIjoiMTYyMzIyNzIwODUyNSJ9.tYs2iRDm5oexDdgcRIZDfjaZ3HEJh1GBfq_smGGmF1UbWqZTDb61Hj7wP2PcrfeM-cT_IZbxNMdd6bQ36Bk4LyNSWrvdFy8Gj6G7OFcnfC5d9_LPPwnqkW-V2-EnbpDY9tlHbNsEFNiGd602Pk3SPOiVk1MQFAFbmjWdFg4E9Dm4cmq1eq6Qr6CAzRUO3o8jxdFoHGRRmEkN1UMr_X9uzPXGCdsL_CAjVgGHxGFGFMhMyiyy-M6vK5ZMVqgYrnNHvH9PUXGDmkQz7BqmxGBdmo6FyqXwb5rL0i2LaEBlSIR6bEXoSREBXdIR82bO0rTP-gDczs7cN5YryYj0TiWgag","content_pack_code":"PATEST2","content_pack_name":"PATEST2","api_url":"http://10.144.92.2:8080/cpbga","api_sync_url":"http://10.144.92.2:8080/cpbga","description":"test2","allow_auto_renew":1,"allow_postpaid":1,"duration_unit":1,"duraction_cycle":1,"allow_duplicate":0,"price":0,"vascloud_service":"DIGITALMARKET","vascloud_package":"PATEST2","renew_price_tklh":2,"allow_prepaid":1,"allow_ezcom":0,"data_plus":30,"data_plus_code":"DC_MBG2_30MB_1D","csp_code":"CP_MEDIA","service_code":"DIGITALMARKET","retry_number":1,"retry_period":8,"package_type":1,"whitelist":"84915285568, 84845148866","mt_short_code":"1376","charging_option":2,"is_check_data_when_unreg":0,"allow_convert_packages":0,"check_bigdata_consumption":0,"comsumption_or_active_time":0,"renew_tel_30_days":0,"api_status":0,"is_sent_mt3":0,"cp_name":"CP NHATANHTEST-DIGITALMARKET"}, result: {"error_code":0,"error_desc":"Success"} 2026-02-27 17:38:31,901 [INFO] (handler.HandlerInterceptorAdapter):122 - Request URL::/product/approveSubmit:: End Time=1772188711901 2026-02-27 17:38:31,901 [INFO] (handler.HandlerInterceptorAdapter):124 - Request URL::/product/approveSubmit:: Time Taken=394 | G9: Pass
A10: TC_004 | B10: Tích hợp hệ thống MBG | C10: Tích hợp đăng ký sản phẩm | D10: Đăng ký thành công sản phẩm | E10: Tích hợp đăng ký gói thành công sang MBG | F10: 2026-02-27 18:38:07 [http-nio-3333-exec-1] c.v.c.s.MbgService Line 125 - INFO ----- REQUEST MBG: {"reason":"","is_uncharge_tkvt":0,"user_name":"DIGITALMARKET","channel":"DIMARKET","cp_name":"CP_MEDIA","trans_id":"17321772192286993866","cp_code":"CP_MEDIA","authen_key":"d3f69314224c795ce7f42010bf75e0d5","mo_syntax":"","start_time":1772192286993,"request_time":1772192286993,"service_code":"DIGITALMARKET","msisdn":"84845148866","expiry_time":"","request_id":1772192286993,"send_sms":1,"order_id":"","content_code":"PATEST2","short_code":"1376","trans_type":"DK"}=> RESPONSE CALL API: {"error_code":0,"message":"Success"} 2026-02-27 18:38:07 [http-nio-3333-exec-1] c.v.c.c.ApiWebsiteController Line 289 - INFO ----- RequestModel(requestId=1772192286836, product_id=530, via=1, channel=SMS, order_id=-1, account_id=-1, msisdn=84845148866, shortCode=1376, moId=726184233, type=1, subId=0)==ResponseModel(reasoncode=0, message=Success, mt=null, mtExtend=null, requestid=1772192286836) | G10: Pass
A11: TC_005 | B11: Tích hợp hệ thống MBG | C11: Tích hợp hủy sản phẩm | D11: Hủy thành công sản phẩm | E11: Tích hợp hủy gói thành công sang MBG | F11: (VH điền log request, respond) | G11: Pass
A12: TC_006 | B12: Tích hợp hệ thống MBG | C12: Tích hợp nhận sự kiện notify đăng ký | D12: Nhận sự kiện notify đăng ký thành công sản phẩm | E12: Tích hợp API notify thành công với MBG | F12: (VH điền log request, respond) | G12: Pass
A13: TC_007 | B13: Đăng ký sản phẩm Bundle | C13: Khai báo sản phẩm và được duyệt lần 1 trên DMP | D13: Khai báo sản phẩm và được duyệt lần 1 trên DMP Thông tin sản phẩm test: - Tên sản phẩm (*) VUIHOCTEST4 - Mã sản phẩm (*) VUIHOCTEST4 - Giá gốc (VND) (*) 0 - Thuê bao nghiệm thu (*) 0915285568,0914353353 - Loại tích hợp (*) Upload file CMS - Quyền lợi Data (*) 30MB/chu kỳ: 1 ngày - Nhóm sản phẩm (*) Giải trí kỹ thuật số – Nội dung số - Loại trừ cước (*) Trừ cước TK linh hoạt - Đầu số gửi MT (*) 1376 - Số lần gọi retry gia hạn sản phẩm (*) 10 - Khoảng cách giữa các lần retry gia hạn sản phẩm (*) 8 ☑ Sản phẩm tự động gia hạn ☑ Áp dụng cho thuê bao trả trước ☑ Áp dụng cho thuê bao trả sau | E13: - Đăng ký thành công sản phẩm - Thuê bao được quản lý trên hệ thống MBG | F13: - Đăng ký thành công sản phẩm - Thuê bao được quản lý trên hệ thống MBG | G13: Pass

Sheet API CSP 
B1: Kết quả | C1: Pass | D1: Fail | E1: Pending | F1: N/A | G1: Untested | H1: Total
C2: =COUNTIF(G4:G1371,"Pass") +countif(G4:G1371,"Accepted") -> 2 | D2: =COUNTIF(G4:G1371,"Fail") -> 0 | E2: =COUNTIF(G4:G1371,"Pending") -> 0 | F2: =COUNTIF(G4:G1371,"N/A") -> 0 | G2: =H2-C2-D2-E2-F2 -> 1 | H2: =COUNTA(E4:E1492) -> 3
A3: ID | B3: Tên Test Case | C3: Tiền điều kiện | D3: Các bước thực hiện | E3: Kết quả mong muốn | F3: Kết quả thực tế | G3: Kết quả | H3: Ngày thực hiện | I3: Mức độ ưu tiên | J3: Bug fix status | K3: Fixed by | L3: Ghi chú
A4: TC_001 | B4: Tích hợp API đăng ký CSP | C4: - Đăng ký thành công sản phẩm nội dung | D4: - Đăng ký thành công sản phẩm nội dung | E4: TÍch hợp API đối tác thành công | F4: 2026-02-25 10:58:18 [http-nio-8181-exec-5] c.v.s.c.MoController Line 38 - INFO ----- MO RECEIVE Request: <ACCESSGW><MODULE>SMSGW</MODULE><MESSAGE_TYPE>NOTIFY</MESSAGE_TYPE><COMMAND><mo_id>725812892</mo_id><destination_address>1376</destination_address><source_address>84845148866</source_address><mo_time>20260225105819</mo_time><content_type>TEXT</content_type><content>dm vho7</content><encode_content>0</encode_content><callback_url>http://10.144.94.5:8181/moApi/receive</callback_url></COMMAND></ACCESSGW> 2026-02-25 10:58:21 [http-nio-3333-exec-3] c.v.c.u.CCGWClient Line 59 - INFO ----- <ACCESSGW> <MODULE>CHARGINGGW</MODULE> <MESSAGETYPE>REQUEST</MESSAGETYPE> <COMMAND> <CCGWRequest servicename="DIGITALMARKET" username ="digitalmarket" password=""> <RequestType>1</RequestType> <SequenceNumber>2026105821</SequenceNumber> <SubId>84845148866</SubId> <Price>3000</Price> <Reason>REG</Reason> <TRANSID>10390000006301771991901414866</TRANSID> <ORIGINALPRICE>3000</ORIGINALPRICE> <PROMOTION>0</PROMOTION> <NOTE>Vuihocngay_1</NOTE> <CHANNEL>SMS</CHANNEL> <ORDER>0</ORDER> <Content> <item contenttype="SUBSCRIPTION" subcontenttype="VI" contentid="2" contentname="Vuihocngay" cpname="SMARTMEDIA-DIGITALMARKET" contentprice="3000" note="" /> </Content> </CCGWRequest> </COMMAND> </ACCESSGW> ==> TKC2026105821 ==> http://10.144.37.10:7001/charginggw/billing ==> <?xml version="1.0" encoding="utf-8" standalone="yes"?><CCGWResponse><Error>0</Error><ErrorDesc>Successful</ErrorDesc><InternalCode/><SequenceNumber>2026105821</SequenceNumber><Price>3000</Price><Promotion>0</Promotion><Note>10390000006301771991901414866_DFS0A3VMADVK606_VCLOUD_91202602251058219000000066_DIGITALMARKET_Vuihocngay_REG_1</Note></CCGWResponse> 2026-02-25 10:58:21 [http-nio-4444-exec-1] c.v.c.u.PostCSP Line 143 - INFO ----- REQUEST REG URL =http://10.144.116.171:8096/cspapi//register -- {"account_cpbg":"","paidtype":"PREPAID","unitduration":1,"serviceCode":"DIGITALMARKET","originalprice":3000,"contentpack":"VHO7","channel":"SMS","duration":1,"timeStart":"20260225105821000000468","subtype":"mobile","requestid":"20260225105823935000000","price":3000,"syntax":"DK VHO7","msisdn":"84845148866","promotion":1} 2026-02-25 10:58:22 [http-nio-4444-exec-1] c.v.c.u.PostCSP Line 146 - INFO ----- RESPONSE REG URL = http://10.144.116.171:8096/cspapi//register --requestid--20260225105823935000000 -- {"password":"","mtExtend":"Cam on Quy khach da lua chon Vui hoc - Duo On luyen. Quy khach vui long truy cap duong link vuihoc.vn de su dung san pham. Chi tiet lien he 18001091(0d).","requestid":"20260225105823935000000","voucher":"","mt":"Quy khach da thanh toan thanh cong goi san pham VHO7 (Gia cuoc 3.000d/24h, gia han theo chu ky). Ma su dung la CQDLWC. De huy, vui long soan HUY VHO7 gui 1376. Truy cap https://dimarket.vn/ de so huu cac san pham voi gia cuoc uu dai chi co tren Digital Market - nen tang TMDT cua VNPT. CSKH 18001091 (0d). Tran trong!","reasoncode":0,"giftcode":"","message":"success","account":""}
A5: TC_003 | B5: Tích hợp API gia hạn CSP | C5: Gia hạn thành công sản phẩm nội dung | D5: Gia hạn thành công sản phẩm nội dung | E5: TÍch hợp API đối tác thành công | F5: 2026-02-25 08:34:30 [http-nio-8181-exec-9] c.v.s.c.MoController Line 38 - INFO ----- MO RECEIVE Request: <ACCESSGW><MODULE>SMSGW</MODULE><MESSAGE_TYPE>NOTIFY</MESSAGE_TYPE><COMMAND><mo_id>725791452</mo_id><destination_address>1376</destination_address><source_address>84888024472</source_address><mo_time>20260225083430</mo_time><content_type>TEXT</content_type><content>DK VHO7</content><encode_content>0</encode_content><callback_url>http://10.144.94.5:8181/moApi/receive</callback_url></COMMAND></ACCESSGW> 2026-02-25 08:34:31 [http-nio-3333-exec-1] c.v.c.u.CCGWClient Line 59 - INFO ----- <ACCESSGW> <MODULE>CHARGINGGW</MODULE> <MESSAGETYPE>REQUEST</MESSAGETYPE> <COMMAND> <CCGWRequest servicename="DIGITALMARKET" username ="digitalmarket" password=""> <RequestType>1</RequestType> <SequenceNumber>2026084501</SequenceNumber> <SubId>84888024472</SubId> <Price>3000</Price> <Reason>RENEW</Reason> <TRANSID>10390000007481771983901798472</TRANSID> <ORIGINALPRICE>3000</ORIGINALPRICE> <PROMOTION>0</PROMOTION> <NOTE>Vuihocngay_1</NOTE> <CHANNEL>SMS</CHANNEL> <ORDER>0</ORDER> <Content> <item contenttype="SUBSCRIPTION" subcontenttype="VI" contentid="2" contentname="Vuihocngay" cpname="SMARTMEDIA-DIGITALMARKET" contentprice="3000" note="" /> </Content> </CCGWRequest> </COMMAND> </ACCESSGW> ==> TKC2026084501 ==> http://10.144.37.10:7001/charginggw/billing ==> <?xml version="1.0" encoding="utf-8" standalone="yes"?><CCGWResponse><Error>0</Error><ErrorDesc>Successful</ErrorDesc><InternalCode/><SequenceNumber>2026084501</SequenceNumber><Price>3000</Price><Promotion>0</Promotion><Note>10390000007481771983901798472_DFS0A3VMADVK606_VCLOUD_91202602250845019000000056_DIGITALMARKET_Vuihocngay_RENEW_1</Note></CCGWResponse> 2026-02-25 08:34:32 [http-nio-4444-exec-9] c.v.c.u.PostCSP Line 146 - INFO ----- RESPONSE REG URL = http://10.144.116.171:8096/cspapi//register --requestid--20260225083437937000000 -- {"password":"","mtExtend":"Cam on Quy khach da lua chon Vui hoc - Duo On luyen. Quy khach vui long truy cap duong link vuihoc.vn de su dung san pham. Chi tiet lien he 18001091(0d).","requestid":"20260225083437937000000","voucher":"","mt":"Quy khach da thanh toan thanh cong goi san pham VHO7 (Gia cuoc 3.000d/24h, gia han theo chu ky). Ma su dung la Y35HJZ. De huy, vui long soan HUY VHO7 gui 1376. Truy cap https://dimarket.vn/ de so huu cac san pham voi gia cuoc uu dai chi co tren Digital Market - nen tang TMDT cua VNPT. CSKH 18001091 (0d). Tran trong!","reasoncode":0,"giftcode":"","message":"success","account":""} | G5: Pass
A6: TC_003 | B6: Tích hợp API hủy CSP | C6: Hủy thành công sản phẩm nội dung | D6: Hủy thành công sản phẩm nội dung | E6: TÍch hợp API đối tác thành công | F6: 2026-02-25 08:46:29 [http-nio-8181-exec-3] c.v.s.c.MoController Line 38 - INFO ----- MO RECEIVE Request: <ACCESSGW><MODULE>SMSGW</MODULE><MESSAGE_TYPE>NOTIFY</MESSAGE_TYPE><COMMAND><mo_id>725793350</mo_id><destination_address>1376</destination_address><source_address>84888024472</source_address><mo_time>20260225084629</mo_time><content_type>TEXT</content_type><content>Huy VHO7</content><encode_content>0</encode_content><callback_url>http://10.144.94.5:8181/moApi/receive</callback_url></COMMAND></ACCESSGW> 2026-02-25 08:46:33 [http-nio-3333-exec-3] c.v.c.c.ApiWebsiteController Line 95 - INFO ----- Request => RequestModel(requestId=1771983991572, product_id=482, via=1, channel=SMS, order_id=-1, account_id=-1, msisdn=84888024472, shortCode=1376, moId=725793350, type=2, subId=0) 2026-02-25 08:46:33 [http-nio-3333-exec-3] c.v.c.c.ApiWebsiteController Line 99 - INFO ----- clientIp=10.144.94.5 2026-02-25 08:46:33 [http-nio-3333-exec-3] c.v.c.u.PostCSP Line 41 - INFO ----- URL=http://10.144.94.15:4444/csp_core/unreg 2026-02-25 08:46:33 [http-nio-3333-exec-3] c.v.c.u.PostCSP Line 42 - INFO ----- param={"url":"http://10.144.116.171:8096/cspapi/","requestid":"20260225084635135000000","contentpack":"VHO7","serviceCode":"DIGITALMARKET","msisdn":"84888024472","account_cpbg":"","subtype":"mobile","paidtype":"PREPAID","timeStart":null,"timeDel":"20260225084633000000134","securecode":null,"syntax":"HUY VHO7","channel":"SMS","promotion":0,"price":0,"originalprice":0,"unitduration":0,"duration":0,"renewresult":0,"pricekm":0,"pricemain":0} 2026-02-25 08:46:33 [http-nio-3333-exec-3] c.v.c.s.UnRegServie Line 155 - INFO ----- CALL CSP CORE unreg{"url":"http://10.144.116.171:8096/cspapi/","requestid":"20260225084635135000000","contentpack":"VHO7","serviceCode":"DIGITALMARKET","msisdn":"84888024472","account_cpbg":"","subtype":"mobile","paidtype":"PREPAID","timeStart":null,"timeDel":"20260225084633000000134","securecode":null,"syntax":"HUY VHO7","channel":"SMS","promotion":0,"price":0,"originalprice":0,"unitduration":0,"duration":0,"renewresult":0,"pricekm":0,"pricemain":0} == {"requestid":"20260225084635135000000","reasoncode":0,"message":"success"} 2026-02-25 08:46:33 [http-nio-3333-exec-3] c.v.c.c.ApiWebsiteController Line 194 - INFO ----- RequestModel(requestId=1771983991572, product_id=482, via=1, channel=SMS, order_id=-1, account_id=-1, msisdn=84888024472, shortCode=1376, moId=725793350, type=2, subId=0)==ResponseModel(reasoncode=0, message=success, mt=null, mtExtend=null, requestid=1771983991572) 2026-02-25 08:46:33 [http-nio-4444-exec-3] c.v.c.u.PostCSP Line 180 - INFO ----- REQUEST UNREG URL =http://10.144.116.171:8096/cspapi//unregister -- {"timedel":"","account_cpbg":"","paidtype":"PREPAID","serviceCode":"DIGITALMARKET","requestid":"20260225084635135000000","contentpack":"VHO7","channel":"SMS","syntax":"HUY VHO7","msisdn":"84888024472","account":""} 2026-02-25 08:46:33 [http-nio-4444-exec-3] c.v.c.u.PostCSP Line 183 - INFO ----- RESPONSE UNREG URL = http://10.144.116.171:8096/cspapi//unregister --requestid--20260225084635135000000 -- {"requestid":"20260225084635135000000","reasoncode":0,"message":"success"} | G6: Pass

Sheet CMS_admin
B1: Kết quả | C1: Pass | D1: Fail | E1: Pending | F1: N/A | G1: Untested | H1: Total
C2: =COUNTIF(G4:G1371,"Pass") +countif(G4:G1371,"Accepted") -> 381 | D2: =COUNTIF(G4:G1371,"Fail") -> 1 | E2: =COUNTIF(G4:G1371,"Pending") -> 1 | F2: =COUNTIF(G4:G1371,"N/A") -> 0 | G2: =H2-C2-D2-E2-F2 -> 1 | H2: =COUNTA(E4:E1492) -> 384
A3: ID | B3: Tên Test Case | C3: Tiền điều kiện | D3: Các bước thực hiện | E3: Kết quả mong muốn | F3: Kết quả thực tế | G3: Kết quả
B4: Quản lý hồ sơ
B5: Danh sách hồ sơ
A6: TC_001 | B6: Kiểm tra truy cập màn hình [Danh sách hồ sơ] | C6: User (Admin/PM) đã đăng nhập CMS Digital Market và được cấp quyền [Quản lý hồ sơ] | D6: 1) Truy cập menu [Quản lý hồ sơ] 2) Mở màn hình [Danh sách hồ sơ] | E6: - Điều hướng đúng tới màn hình [Danh sách hồ sơ] - Màn hình hiển thị đầy đủ các khu vực: khu tìm kiếm/lọc, bảng danh sách, phân trang (nếu có dữ liệu) | G6: Pass
A7: TC_002 | B7: Kiểm tra hiển thị dữ liệu mặc định khi mở màn hình [Danh sách hồ sơ] | C7: Có tối thiểu 2 hồ sơ tồn tại | D7: 1) Mở màn hình [Danh sách hồ sơ] lần đầu | E7: - Hệ thống tự động load danh sách hồ sơ (không cần bấm button[Tìm kiếm]) - Hiển thị tất cả hồ sơ theo phạm vi dữ liệu đã confirm (không ẩn trạng thái nào) | G7: Pass
A8: TC_003 | B8: Kiểm tra thứ tự sắp xếp mặc định theo [created_date] từ mới đến cũ | C8: Có tối thiểu 3 hồ sơ với [created_date] khác nhau | D8: 1) Mở màn hình [Danh sách hồ sơ] 2) Quan sát thứ tự các dòng | E8: - Danh sách được sắp xếp theo [created_date] giảm dần (mới → cũ) | G8: Pass
A9: TC_004 | B9: Kiểm tra phân trang với [PageSize] tối đa 20 bản ghi/trang | C9: Có > 20 hồ sơ | D9: 1) Mở màn hình [Danh sách hồ sơ] 2) Quan sát số dòng hiển thị trên trang 1 | E9: - Mỗi trang hiển thị tối đa 20 bản ghi | F9: Đang có 10 bản ghi/ 1trang | G9: Accepted
A10: TC_005 | B10: Kiểm tra chuyển trang khi bấm điều khiển phân trang | C10: Có > 20 hồ sơ | D10: 1) Ở trang 1, bấm trang 2 (hoặc button điều hướng next) | E10: - Danh sách chuyển sang trang được chọn - Dữ liệu hiển thị đúng theo trang | G10: Pass
A11: TC_006 | B11: Kiểm tra [PageLength] không giới hạn | C11: Có nhiều hơn 2 trang dữ liệu | D11: 1) Lần lượt chuyển qua nhiều trang (1 → 2 → 3 …) | E11: - Có thể điều hướng qua tất cả các trang dữ liệu - Không bị giới hạn số trang tối đa | G11: Pass
A12: TC_007 | B12: Kiểm tra hiển thị các cột trên bảng [Danh sách hồ sơ] | C12: Đang ở màn hình [Danh sách hồ sơ] | D12: 1) Quan sát header bảng | E12: - Bảng hiển thị đầy đủ các cột theo SRS (ví dụ: [STT], [Tên CP], [Mã CP], [Tên văn bản], [Loại văn bản], [Hình thức], [Trạng thái hồ sơ], [File type], [Ngày cập nhật cuối], [Ghi chú], [Thao tác]) | F12: Thiếu các trường: File type, Ghi chú => BA đồng ý | G12: Pass
A13: TC_008 | B13: Kiểm tra tìm kiếm theo field [Tên văn bản] dạng contain | C13: Có hồ sơ có [Tên văn bản] chứa chuỗi “ABC” | D13: 1) Nhập “ABC” vào field[Tên văn bản] 2) Bấm button[Tìm kiếm] | E13: - Danh sách trả về các hồ sơ có [Tên văn bản] chứa “ABC” | G13: Pass
A14: TC_009 | B14: Kiểm tra tìm kiếm theo field [Tên văn bản] không phân biệt hoa/thường | C14: Có hồ sơ có [Tên văn bản] chứa “abc” | D14: 1) Nhập “ABC” vào field[Tên văn bản] 2) Bấm button[Tìm kiếm] | E14: - Kết quả tìm kiếm vẫn trả về các hồ sơ có [Tên văn bản] chứa “abc/ABC” - Tìm kiếm không phân biệt hoa/thường | G14: Pass
A15: TC_010 | B15: Kiểm tra tìm kiếm theo field [Tên văn bản] khi không có kết quả | C15: Đang ở màn hình [Danh sách hồ sơ] | D15: 1) Nhập chuỗi không tồn tại vào field[Tên văn bản] 2) Bấm button[Tìm kiếm] | E15: - Bảng kết quả không có bản ghi phù hợp - Hiển thị trạng thái “không có dữ liệu” (theo UI hệ thống) | G15: Pass
A16: TC_011 | B16: Kiểm tra tìm kiếm khi để trống field[Tên văn bản] | C16: Đang ở màn hình [Danh sách hồ sơ] | D16: 1) Xóa trống field[Tên văn bản] 2) Bấm button[Tìm kiếm] | E16: - Hệ thống trả về danh sách hồ sơ theo điều kiện lọc khác (nếu có) - Nếu không chọn lọc nào khác thì trả về tất cả hồ sơ | G16: Pass
A17: TC_012 | B17: Kiểm tra bộ lọc [Trạng thái] có đúng 3 giá trị | C17: Đang ở màn hình [Danh sách hồ sơ] | D17: 1) Mở droplist field[Trạng thái] | E17: - Droplist field[Trạng thái] hiển thị đúng 3 giá trị: [Tất cả], [Chờ duyệt], [Đã duyệt] | F17: Theo Q&A bộ lọc chỉ có 3 trạng thái: Tất cả, Chờ duyệt, Đã duyệt | G17: Accepted
A18: TC_013 | B18: Kiểm tra giá trị mặc định của field[Trạng thái] | C18: Đang ở màn hình [Danh sách hồ sơ] | D18: 1) Mở màn hình [Danh sách hồ sơ] | E18: - Field[Trạng thái] mặc định chọn [Tất cả] | G18: Pass
A19: TC_014 | B19: Kiểm tra lọc theo trạng thái [Chờ duyệt] | C19: Có hồ sơ ở trạng thái [Chờ duyệt] | D19: 1) Chọn [Chờ duyệt] tại field[Trạng thái] 2) Bấm button[Tìm kiếm] | E19: - Danh sách chỉ hiển thị các hồ sơ có trạng thái [Chờ duyệt] | G19: Pass
A20: TC_015 | B20: Kiểm tra lọc theo trạng thái [Đã duyệt] | C20: Có hồ sơ ở trạng thái [Đã duyệt] | D20: 1) Chọn [Đã duyệt] tại field[Trạng thái] 2) Bấm button[Tìm kiếm] | E20: - Danh sách chỉ hiển thị các hồ sơ có trạng thái [Đã duyệt] | G20: Pass
A21: TC_016 | B21: Kiểm tra lọc theo trạng thái [Tất cả] | C21: Có nhiều hồ sơ ở nhiều trạng thái | D21: 1) Chọn [Tất cả] tại field[Trạng thái] 2) Bấm button[Tìm kiếm] | E21: - Danh sách hiển thị hồ sơ của tất cả trạng thái trong phạm vi dữ liệu | G21: Pass
A22: TC_017 | B22: Kiểm tra tìm kiếm kết hợp [Tên văn bản] + [Trạng thái] | C22: Có dữ liệu thỏa điều kiện kết hợp | D22: 1) Nhập “ABC” vào field[Tên văn bản] 2) Chọn [Chờ duyệt] tại field[Trạng thái] 3) Bấm button[Tìm kiếm] | E22: - Kết quả chỉ gồm hồ sơ có [Tên văn bản] chứa “ABC” - Và có [Trạng thái] = [Chờ duyệt] | G22: Pass
A23: TC_023 | B23: Kiểm tra hiển thị thao tác [Duyệt] theo trạng thái [Chờ duyệt] | C23: Có hồ sơ trạng thái [Chờ duyệt] | D23: 1) Quan sát cột [Thao tác] tại hồ sơ [Chờ duyệt] | E23: - Hồ sơ [Chờ duyệt] hiển thị thao tác [Duyệt] | F23: Hiển thị chung cả duyệt và từ chối trong popup | G23: Pass
A24: TC_024 | B24: Kiểm tra hiển thị thao tác [Từ chối] theo trạng thái [Chờ duyệt] | C24: Có hồ sơ trạng thái [Chờ duyệt] | D24: 1) Quan sát cột [Thao tác] tại hồ sơ [Chờ duyệt] | E24: - Hồ sơ [Chờ duyệt] hiển thị thao tác [Từ chối] | F24: Hiển thị chung cả duyệt và từ chối trong popup | G24: Pass
A25: TC_027 | B25: Kiểm tra button[Duyệt] trên popup duyệt hồ sơ | C25: Có popup [Duyệt/Từ chối hồ sơ] đang mở | D25: 1) Bấm button[Duyệt] | E25: - Hồ sơ được duyệt thành công - Trạng thái hồ sơ chuyển sang [Đã duyệt] - Danh sách được cập nhật theo trạng thái mới | G25: Pass
A26: TC_028 | B26: Kiểm tra button[Từ chối] trên popup duyệt hồ sơ khi chưa nhập field[Lý do] | C26: Có popup [Duyệt/Từ chối hồ sơ] đang mở | D26: 1) Để trống field[Lý do] 2) Bấm button[Từ chối] | E26: - Hiển thị validate yêu cầu nhập field[Lý do] - Không thực hiện từ chối khi chưa có [Lý do] | G26: Pass
A27: TC_029 | B27: Kiểm tra button[Từ chối] trên popup duyệt hồ sơ khi đã nhập field[Lý do] | C27: Có popup [Duyệt/Từ chối hồ sơ] đang mở | D27: 1) Nhập giá trị vào field[Lý do] 2) Bấm button[Từ chối] | E27: - Hồ sơ bị từ chối thành công - Trạng thái hồ sơ cập nhật thành từ chối | G27: Pass
A28: TC_030 | B28: Kiểm tra mở popup xác nhận khi thực hiện thao tác [Xóa] | C28: Có hồ sơ [Chờ duyệt] | D28: 1) Tại 1 hồ sơ [Chờ duyệt], bấm thao tác [Xóa] | E28: - Hiển thị popup xác nhận xóa đúng nội dung theo SRS (có [Tên hồ sơ] và [Tên đối tác]) | G28: Pass
A29: TC_031 | B29: Kiểm tra button[Đồng ý] trên popup [Xóa hồ sơ] | C29: Có popup [Xóa hồ sơ] đang mở | D29: 1) Bấm button[Đồng ý] | E29: - Xóa hồ sơ thành công - Hồ sơ bị ẩn khỏi danh sách ngay sau khi xác nhận xóa - Không hiển thị trạng thái “đã xóa” trên danh sách (theo Q&A) | G29: Pass
A30: TC_032 | B30: Kiểm tra button[Hủy] trên popup [Xóa hồ sơ] | C30: Có popup [Xóa hồ sơ] đang mở | D30: 1) Bấm button[Hủy] | E30: - Đóng popup - Hồ sơ vẫn giữ nguyên trên danh sách - Không có thay đổi trạng thái/dữ liệu | G30: Pass
A31: TC_036 | B31: Kiểm tra tìm kiếm giữ đúng thứ tự sắp xếp mặc định | C31: Có nhiều hồ sơ thỏa điều kiện tìm kiếm | D31: 1) Nhập điều kiện tìm kiếm (ví dụ field [Tên văn bản] = “A”) 2) Bấm button [Tìm kiếm] | E31: - Kết quả tìm kiếm vẫn sắp xếp theo [created_date] giảm dần (mới → cũ) | G31: Pass
B32: Thêm hồ sơ
A33: TC_048 | B33: Kiểm tra điều hướng khi bấm button [Thêm mới hồ sơ] từ màn hình [Danh sách hồ sơ] | C33: Admin đã đăng nhập và đang ở màn hình [Danh sách hồ sơ] | D33: 1) Bấm button[Thêm mới hồ sơ] | E33: - Điều hướng sang màn hình [Thêm mới hồ sơ] | G33: Pass
A34: TC_049 | B34: Kiểm tra hiển thị các trường thông tin trên màn hình [Thêm mới hồ sơ] | C34: Admin đang ở màn hình [Thêm mới hồ sơ] | D34: 1) Quan sát form | E34: - Tên CP - Mã CP - Hiển thị field[Tên văn bản] - Hiển thị field[Loại văn bản] - Hiển thị field[Hình thức văn bản] - Hiển thị field[Ghi chú] - Hiển thị button[Upload file] - Hiển thị button[Cập nhật] | G34: Pass
A35: TC_050 | B35: Kiểm tra danh sách field[Loại văn bản] là cố định giá trị | C35: Admin đang ở màn hình [Thêm mới hồ sơ] | D35: 1) Mở dropdown field[Loại văn bản] | E35: - Dropdown field[Loại văn bản] hiển thị danh sách giá trị cố định theo cấu hình hệ thống - Không cho phép nhập tay giá trị ngoài danh sách | G35: Pass
A36: TC_051 | B36: Kiểm tra validate bắt buộc của field[Tên văn bản] | C36: Admin đang ở màn hình [Thêm mới hồ sơ] | D36: 1) Để trống field[Tên văn bản] 2) Nhập/Chọn hợp lệ các field bắt buộc khác 3) Bấm button[Cập nhật] và xác nhận OK (nếu có popup) | E36: - Hiển thị thông báo lỗi tại field[Tên văn bản] (yêu cầu nhập) - Không tạo mới hồ sơ | G36: Pass
A37: TC_052 | B37: Kiểm tra validate bắt buộc của field[Loại văn bản] | C37: Admin đang ở màn hình [Thêm mới hồ sơ] | D37: 1) Không chọn giá trị field[Loại văn bản] (để mặc định “Chọn” nếu có) 2) Nhập/Chọn hợp lệ các field bắt buộc khác 3) Bấm button[Cập nhật] và xác nhận OK | E37: - Hiển thị thông báo lỗi tại field[Loại văn bản] (yêu cầu chọn) - Không tạo mới hồ sơ | G37: Pass
A38: TC_053 | B38: Kiểm tra validate bắt buộc của field[Hình thức văn bản] | C38: Admin đang ở màn hình [Thêm mới hồ sơ] | D38: 1) Không chọn giá trị field[Hình thức văn bản] (để mặc định “Chọn” nếu có) 2) Nhập/Chọn hợp lệ các field bắt buộc khác 3) Bấm button[Cập nhật] và xác nhận OK | E38: - Hiển thị thông báo lỗi tại field[Hình thức văn bản] (yêu cầu chọn) - Không tạo mới hồ sơ | G38: Pass
A39: TC_054 | B39: Kiểm tra chỉ cho upload 1 file cho mỗi hồ sơ | C39: Admin đang ở màn hình [Thêm mới hồ sơ] | D39: 1) Bấm button[Upload file] và upload file_1 hợp lệ 2) Bấm button[Upload file] và chọn upload file_2 | E39: - Hệ thống chỉ cho phép gắn 1 file cho hồ sơ - Nếu upload lần 2: file mới thay thế file cũ hoặc hệ thống chặn không cho upload thêm (theo cơ chế hiện có trên UI) | G39: Pass
A40: TC_055 | B40: Kiểm tra validate định dạng file upload chỉ cho phép [.pdf] | C40: Admin đang ở màn hình [Thêm mới hồ sơ] | D40: 1) Bấm button[Upload file] 2) Chọn file không phải .pdf (ví dụ .docx/.png) | E40: - Hệ thống không chấp nhận file upload - Hiển thị thông báo lỗi định dạng file (chỉ cho phép PDF) | G40: Pass
...

Sheet CMS_CP
B1: Kết quả | C1: Pass | D1: Fail | E1: Pending | F1: N/A | G1: Untested | H1: Total
C2: =COUNTIF(G4:G1371,"Pass") +countif(G4:G1371,"Accepted") -> 202 | D2: =COUNTIF(G4:G1371,"Fail") -> 0 | E2: =COUNTIF(G4:G1371,"Pending") -> 2 | F2: =COUNTIF(G4:G1371,"N/A") -> 0 | G2: =H2-C2-D2-E2-F2 -> 0 | H2: =COUNTA(E4:E1492) -> 204
A3: ID | B3: Tên Test Case | C3: Tiền điều kiện | D3: Các bước thực hiện | E3: Kết quả mong muốn | F3: Kết quả thực tế | G3: Kết quả
B4: Quản lý hồ sơ
B5: Xem danh sách hồ sơ
A6: TC_001 | B6: Kiểm tra truy cập màn hình Danh sách hồ sơ | C6: CP có tài khoản và quyền truy cập CMS | D6: 1) Đăng nhập CMS bằng tài khoản CP 2) Vào module Quản lý Hồ sơ | E6: - Hệ thống hiển thị màn hình Danh sách hồ sơ - Không xuất hiện thông báo lỗi - Hiển thị bảng danh sách hồ sơ của CP đang đăng nhập | G6: Pass
A7: TC_002 | B7: Kiểm tra hiển thị hồ sơ theo đúng CP đăng nhập | C7: Có 2 CP khác nhau, mỗi CP có ≥1 hồ sơ | D7: 1) Login CP_A → mở danh sách 2) Ghi nhận dữ liệu hiển thị 3) Logout 4) Login CP_B → mở danh sách | E7: - Khi login CP_A, chỉ hiển thị các hồ sơ thuộc CP_A - Khi login CP_B, chỉ hiển thị các hồ sơ thuộc CP_B - Không hiển thị chéo dữ liệu giữa các CP | G7: Pass
A8: TC_003 | B8: Kiểm tra hiển thị các cột trên Danh sách hồ sơ | C8: CP có ít nhất 1 hồ sơ | D8: 1) Mở Danh sách hồ sơ | E8: - Bảng hiển thị các cột: STT, Tên văn bản, Loại văn bản, Hình thức, Trạng thái hồ sơ, Ngày cập nhật cuối, tác - Giao diện không bị thiếu hoặc lệch cột | G8: Pass
A9: TC_006 | B9: Kiểm tra tìm kiếm theo Tên văn bản (khớp chính xác) | C9: Có hồ sơ tên “Hồ sơ ABC” | D9: 1) Nhập “Hồ sơ ABC” vào ô tìm kiếm 2) Thực hiện tìm kiếm | E9: - Danh sách chỉ hiển thị hồ sơ có Tên văn bản là “Hồ sơ ABC” - Không hiển thị các hồ sơ không trùng tên | G9: Pass
A10: TC_007 | B10: Kiểm tra tìm kiếm theo Tên văn bản (gần đúng) | C10: Có hồ sơ tên “Hồ sơ ABC” | D10: 1) Nhập “ABC” vào ô tìm kiếm 2) Thực hiện tìm kiếm | E10: - Danh sách hiển thị các hồ sơ có Tên văn bản chứa “ABC” - Bao gồm hồ sơ “Hồ sơ ABC” - Không hiển thị hồ sơ không liên quan | G10: Pass
A11: TC_008 | B11: Kiểm tra tìm kiếm khi không có dữ liệu phù hợp | C11: CP có dữ liệu hồ sơ | D11: 1) Nhập chuỗi không tồn tại (vd: “ZZZ123”) 2) Thực hiện tìm kiếm | E11: - Danh sách không hiển thị bản ghi nào - Có thể hiển thị trạng thái rỗng/không có dữ liệu - Không phát sinh lỗi | G11: Pass
A12: TC_010 | B12: Kiểm tra hiển thị Ngày cập nhật cuối trên Danh sách hồ sơ | C12: Có hồ sơ đã được tạo hoặc chỉnh sửa | D12: 1) Mở Danh sách | E12: - Cột “Ngày cập nhật cuối” hiển thị thời gian tác động gần nhất lên hồ sơ - Thời gian hiển thị khớp với thao tác tạo hoặc chỉnh sửa gần nhất | G12: Pass
A13: TC_011 | B13: Kiểm tra điều hướng khi bấm button “Thêm mới hồ sơ” | C13: CP đang ở màn hình Danh sách hồ sơ | D13: 1) Tại màn Danh sách hồ sơ, click button “Thêm mới hồ sơ” | E13: - Hệ thống điều hướng sang màn hình Thêm hồ sơ - Hiển thị form nhập thông tin hồ sơ (Tên văn bản, Loại văn bản, Hình thức văn bản, Ghi chú) - Hiển thị các button: Upload, Thêm hồ sơ, Hủy, Gửi phê duyệt - Không xuất hiện thông báo lỗi | G13: Pass
B14: Thêm mới hồ sơ
A15: TC_012 | B15: Kiểm tra hiển thị màn hình Thêm hồ sơ | C15: CP có quyền khởi tạo hồ sơ | D15: 1) Từ Danh sách hồ sơ, bấm button “Thêm mới hồ sơ” | E15: - Hệ thống hiển thị màn hình Thêm hồ sơ - Hiển thị các trường: Tên văn bản, Loại văn bản, Hình thức văn bản, Ghi chú - Hiển thị các button: Upload, Thêm hồ sơ, Hủy, Gửi phê duyệt | G15: Pass
A16: TC_013 | B16: Kiểm tra nhập đầy đủ thông tin trên màn Thêm hồ sơ | C16: CP đang ở màn Thêm hồ sơ | D16: 1) Nhập Tên văn bản 2) Chọn Loại văn bản 3) Chọn Hình thức văn bản 4) Nhập Ghi chú | E16: - Các trường cho phép nhập/chọn dữ liệu bình thường - Dữ liệu hiển thị đúng với giá trị người dùng đã nhập | G16: Pass
A17: TC_015 | B17: Kiểm tra lưu hồ sơ bằng button “Thêm hồ sơ” | C17: CP đã nhập đầy đủ thông tin và upload file | D17: 1) Bấm button “Thêm hồ sơ” | E17: - Hệ thống lưu hồ sơ mới - Điều hướng về màn Danh sách hồ sơ - Hiển thị bản ghi hồ sơ vừa tạo trong danh sách với đầy đủ thông tin đã nhập | G17: Pass
A18: TC_016 | B18: Kiểm tra validate khi thiếu thông tin bắt buộc | C18: CP đang ở màn Thêm hồ sơ | D18: 1) Để trống một hoặc nhiều trường bắt buộc 2) Bấm button “Thêm hồ sơ” | E18: - Hệ thống không lưu hồ sơ - Hiển thị thông báo yêu cầu nhập các trường bắt buộc - Giữ nguyên màn hình Thêm hồ sơ | G18: Pass
A19: TC_017 | B19: Kiểm tra popup khi bấm button “Gửi phê duyệt” | C19: CP đang ở màn Thêm hồ sơ | D19: 1) Bấm button “Gửi phê duyệt” | E19: - Hiển thị popup xác nhận - Nội dung: “Bạn chắc chắn muốn Gửi phê duyệt hồ sơ?” - Có hai button: OK và Hủy | G19: Pass
A20: TC_018 | B20: Kiểm tra hủy gửi phê duyệt tại popup | C20: Đang hiển thị popup Gửi phê duyệt | D20: 1) Bấm button “Hủy” | E20: - Popup đóng - Giữ nguyên màn hình Thêm hồ sơ - Dữ liệu đã nhập không bị mất | G20: Pass
A21: TC_019 | B21: Kiểm tra gửi phê duyệt hồ sơ | C21: CP đã nhập đầy đủ thông tin và upload file | D21: 1) Bấm button “Gửi phê duyệt” 2) Bấm button “OK” | E21: - Hồ sơ được chuyển lên Admin để phê duyệt - Thông tin hồ sơ được lưu vào hệ thống - Điều hướng về màn Danh sách hồ sơ - Hồ sơ hiển thị trong danh sách với trạng thái “Chờ phê duyệt” | G21: Pass
A22: TC_020 | B22: Kiểm tra hủy thao tác Thêm hồ sơ | C22: CP đang ở màn Thêm hồ sơ | D22: 1) Bấm button “Hủy” | E22: - Hệ thống hủy thao tác thêm hồ sơ - Điều hướng về màn hình trước đó (Danh sách hồ sơ hoặc Trang chủ theo thiết kế) - Không tạo mới hồ sơ trong hệ thống | G22: Pass
B23: Chỉnh sửa hồ sơ
A24: TC_021 | B24: Kiểm tra điều hướng màn hình khi bấm vào button “Chỉnh sửa hồ sơ” | C24: CP có ít nhất 1 hồ sơ trên Danh sách | D24: 1) Tại màn Danh sách hồ sơ, chọn thao tác “Chỉnh sửa hồ sơ” | E24: - Hệ thống điều hướng sang màn hình Chỉnh sửa hồ sơ - Hiển thị đầy đủ thông tin hiện tại của hồ sơ (Tên văn bản, Loại, Hình thức, Ghi chú, file đã upload) | G24: Pass
A25: TC_022 | B25: Kiểm tra hiển thị các trường và button trên màn Chỉnh sửa hồ sơ | C25: CP đang ở màn Chỉnh sửa hồ sơ | D25: 1) Quan sát giao diện màn hình | E25: - Hiển thị các trường: Tên văn bản, Loại văn bản, Hình thức văn bản, Ghi chú - Hiển thị file đã upload trước đó - Hiển thị các button: Upload, Gửi phê duyệt, Hủy | G25: Pass
A26: TC_023 | B26: Kiểm tra chỉnh sửa thông tin hồ sơ | C26: CP đang ở màn Chỉnh sửa hồ sơ | D26: 1) Thay đổi Tên văn bản/Ghi chú/Loại/Hình thức 2) Quan sát dữ liệu trên form | E26: - Các trường cho phép chỉnh sửa bình thường - Giá trị mới hiển thị đúng theo dữ liệu CP đã nhập | G26: Pass
A27: TC_025 | B27: Kiểm tra popup khi bấm button “Gửi phê duyệt” ở màn Chỉnh sửa | C27: CP đang ở màn Chỉnh sửa hồ sơ | D27: 1) Bấm button “Gửi phê duyệt” | E27: - Hiển thị popup xác nhận - Nội dung: “Bạn chắc chắn muốn Gửi phê duyệt thông tin?” - Có hai button: OK và Hủy | G27: Pass
A28: TC_026 | B28: Kiểm tra hủy gửi phê duyệt tại popup khi chỉnh sửa | C28: Đang hiển thị popup Gửi phê duyệt | D28: 1) Bấm button “Hủy” | E28: - Popup đóng - Giữ nguyên màn hình Chỉnh sửa hồ sơ - Dữ liệu đã chỉnh sửa chưa bị mất | G28: Pass
A29: TC_027 | B29: Kiểm tra gửi phê duyệt sau khi chỉnh sửa hồ sơ | C29: CP đã chỉnh sửa thông tin hợp lệ | D29: 1) Bấm button “Gửi phê duyệt” 2) Bấm button “OK” | E29: - Hệ thống lưu thông tin hồ sơ đã chỉnh sửa - Điều hướng về màn Danh sách hồ sơ - Hồ sơ hiển thị trong danh sách với trạng thái “Chờ phê duyệt” | G29: Pass
A30: TC_028 | B30: Kiểm tra trạng thái hồ sơ sau khi chỉnh sửa | C30: Có hồ sơ vừa được gửi phê duyệt sau chỉnh sửa | D30: 1) Quay về Danh sách hồ sơ | E30: - Trạng thái hồ sơ hiển thị là “Chờ phê duyệt” | G30: Pass
A31: TC_029 | B31: Kiểm tra popup khi bấm button “Hủy” ở màn Chỉnh sửa | C31: CP đang ở màn Chỉnh sửa hồ sơ | D31: 1) Bấm button “Hủy” | E31: - Hiển thị popup xác nhận “Bạn chắc chắn muốn hủy?” - Có hai button: OK và Hủy | G31: Pass
A32: TC_030 | B32: Kiểm tra hủy thao tác hủy ở màn Chỉnh sửa | C32: Đang hiển thị popup “Bạn chắc chắn muốn hủy?” | D32: 1) Bấm button “Hủy” | E32: - Popup đóng - Giữ nguyên màn hình Chỉnh sửa hồ sơ - Trạng thái hồ sơ không thay đổi | G32: Pass
A33: TC_031 | B33: Kiểm tra xác nhận hủy và quay về trang chủ | C33: Đang hiển thị popup “Bạn chắc chắn muốn hủy?” | D33: 1) Bấm button “OK” | E33: - Hệ thống điều hướng về trang chủ - Trạng thái hồ sơ được giữ nguyên | G33: Pass
B34: Xóa hồ sơ
A35: TC_032 | B35: Kiểm tra hiển thị popup khi bấm icon Xóa hồ sơ | C35: CP đang ở màn hình Danh sách hồ sơ và có ít nhất 1 hồ sơ | D35: 1) Tại màn Danh sách hồ sơ, bấm icon Xóa của một hồ sơ | E35: - Hiển thị popup xác nhận xóa hồ sơ - Nội dung popup: “Bạn có muốn xóa hồ sơ <Tên hồ sơ>?” - Có hai button: Đồng ý và Hủy | G35: Pass
A36: TC_033 | B36: Kiểm tra hủy xóa hồ sơ tại popup | C36: Đang hiển thị popup Xóa hồ sơ | D36: 1) Bấm button “Hủy” | E36: - Popup đóng - Hồ sơ vẫn hiển thị trên Danh sách hồ sơ - Không có thay đổi dữ liệu | G36: Pass
A37: TC_034 | B37: Kiểm tra xóa hồ sơ ở trạng thái “Chờ duyệt” | C37: Có hồ sơ ở trạng thái “Chờ duyệt” | D37: 1) Bấm icon Xóa của hồ sơ “Chờ duyệt” 2) Bấm button “Đồng ý” | E37: - Hồ sơ bị xóa khỏi hệ thống của CP - Hồ sơ không còn hiển thị trên Danh sách hồ sơ | G37: Pass
A38: TC_035 | B38: Kiểm tra xóa hồ sơ ở trạng thái “Từ chối” | C38: Có hồ sơ ở trạng thái “Từ chối” | D38: 1) Bấm icon Xóa của hồ sơ “Từ chối” 2) Bấm button “Đồng ý” | E38: - Hồ sơ bị xóa khỏi hệ thống của CP - Hồ sơ không còn hiển thị trên Danh sách hồ sơ | G38: Pass
B39: Quản lý đối tác
B40: Thông tin đối tác
...

Sheet UAT kịch bản gói Bundle
B1: Kết quả | C1: Pass | D1: Fail | E1: Pending | F1: N/A | G1: Untested | H1: Total
C2: =COUNTIF(F4:F1371,"Pass") +countif(F4:F1371,"Accepted") -> 13 | D2: =COUNTIF(F4:F1371,"Fail") -> 0 | E2: =COUNTIF(F4:F1371,"Pending") -> 0 | F2: =COUNTIF(F4:F1371,"N/A") -> 1 | G2: =H2-C2-D2-E2-F2 -> 0 | H2: =COUNTA(E5:E1492) -> 14
B3: ** Sử dụng đầu số 1376 và cước 0đ do chưa có sản phẩm được thẩm định
B4: Nội dung | C4: TB, thời gian | D4: Cú pháp | E4: MT | F4: Kết quả
A5: I | B5: Đăng ký
A6: 1 | B6: Thuê bao thanh toán thành công | D6: Soạn DK PAtest2 gửi 1376 | E6: Trường hợp sản phẩm có gia hạn theo chu kỳ (gói cước dịch vụ số,…): MT1: Quy khach da thanh toan thanh cong goi san pham KidsUp Tieng Viet (Gia cuoc 3000d/ngay, gia han tu dong). De huy, vui long soan HUY PAtest gửi 1376. Truy cap https://dimarket.vn/ de so huu cac san pham voi gia cuoc uu dai chi co tren Digital Market – nen tang TMDT cua VNPT. CSKH 18001091 (0d). Tran trong! MT2: Cam on Quy khach da lua chon KidsUp Tieng Viet - ung dung hoc doc Tieng Viet danh cho tre tu 4 den 8 tuoi. Truy cap https://www.kidsup.net/kidsup-tieng-viet/ de tai ve ung dung va kich hoat License su dung dich vu. Chi tiet lien he 18001091(0d). | F6: Pass
A7: 2 | B7: Thuê bao thanh toán không thành công do lỗi hệ thống | D7: Soạn DM PAtest gửi 1376 | E7: "Hệ thống trả MT: Yeu cau cua Qua khach chua duoc thuc hien do he thong dang ban. Vui long thu lai sau. CSKH 18001091 (0d). Tran trong! | F7: N/A
A8: 3 | B8: Thuê bao thanh toán không thành công do không đủ số dư trong tài khoản | D8: Soạn DM PAtest gửi 1376 | E8: "Hệ thống trả MT: Giao dich khong thanh cong do thue bao khong du tien trong tai khoan. Vui long nap tien https://my.vnpt.com.vn/adv/nt (TB tra truoc), soan *105*[Mã thẻ]# (TB tra sau) va thu lai hoac thanh toan qua VNPT Pay tai [Link QR Code] (hieu luc 10 phut). CSKH 18001091 (0d). Tran trong! | F8: Pass
A9: 4 | B9: Thuê bao thanh toán không thành công do sai mã sản phẩm/mã sản phẩm không tồn tại | D9: Soạn DM [Mã sản phẩm sai] gửi 1376 hoặc DK [Mã sản phẩm sai] gửi 1376 | E9: "Hệ thống trả MT: Yeu cau cua Quy khach chua duoc thuc hien do ma san pham khong dung. Chi tiet LH 18001091 (0d) hoac truy cap https://dimarket.vn/ Digital Market – nen tang TMDT cua VNPT. Tran trong! | F9: Pass
A10: II | B10: Gia hạn
A11: 5 | B11: Hệ thống gia hạn thành công | D11: 1. Kiểm tra MT gia hạn từ đầu số 1376 | E11: MT1: Quy khach da gia han thanh cong goi san pham KidsUp Tieng Viet (Gia cuoc 3000d/ngay, gia han tu dong). De huy, vui long soan HUY PAtest gửi 1376. Truy cap https://dimarket.vn/ de so huu cac san pham voi gia cuoc uu dai chi co tren Digital Market – nen tang TMDT cua VNPT. CSKH 18001091 (0d). Tran trong! MT2: Cam on Quy khach da lua chon KidsUp Tieng Viet - ung dung hoc doc Tieng Viet danh cho tre tu 4 den 8 tuoi. Truy cap https://www.kidsup.net/kidsup-tieng-viet/ de tai ve ung dung va kich hoat License su dung dich vu. Chi tiet lien he 18001091(0d). | F11: Pass
A12: 6 | B12: Hệ thống gia hạn không thành công | D12: 1. Kiểm tra MT gia hạn từ đầu số 1376 | E12: "Hệ thống trả MT: Goi san pham KidsUp Tieng Viet cua Quy khach gia han khong thanh cong do thue bao khong du so du 3000d trong tai khoan. Vui long nap tien https://my.vnpt.com.vn/adv/nt (TB tra truoc), soan *105*[Mã thẻ]# (TB tra sau) hoac thanh toan qua VNPT Pay tai [Link QR Code] (hieu luc 10 phut) de tiep tuc su dung. Neu khong con nhu cau, soan HUY PAtest gửi 1376. CSKH 18001091 (0d). Tran trong! | F12: Pass
A13: III | B13: Hủy
A14: 7 | B14: Thuê bao hủy thành công | D14: "1. Hủy thanh toán sản phẩm Soạn HUY PAtest gửi 1376" | E14: Hệ thống trả MT: Quy khach da huy gia han goi san pham KidsUp Tieng Viet thanh cong va duoc su dung den {hh:mm dd/mm/yyyy}. Soan DK KIDTV gửi 1376 (Gia cuoc 3000d/ngay) de tiep tuc su dung sau thoi gian nay. Truy cap https://dimarket.vn/ de so huu cac san pham voi gia cuoc uu dai chi co tren Digital Market – nen tang TMDT cua VNPT. CSKH 18001091 (0d). Tran trong! (hh:mm dd/mm/yyyy là thời điểm kết thúc chu kỳ thanh toán hiện tại) | F14: Pass
A15: 8 | B15: Thuê bao hủy không thành công do sai mã sản phẩm/mã sản phẩm không tồn tại | D15: "1. Hủy thanh toán sản phẩm Soạn HUY [Mã sản phẩm sai] gửi 1376" | E15: "Hệ thống trả MT: Yeu cau cua Quy khach chua duoc thuc hien do ma san pham khong dung. Chi tiet LH 18001091 (0d) hoac truy cap Digital Market https://dimarket.vn/ – nen tang TMDT cua VNPT. Tran trong! | F15: Pass
A16: 9 | B16: Thuê bao hủy không thành công do sản phẩm không phải gói gia hạn | D16: "1. Hủy thanh toán sản phẩm Soạn HUY [Mã sản phẩm không phải gói gia hạn] gửi 1376" | E16: "Hệ thống trả MT: Yeu cau cua Quy khach chua duoc thuc hien do san pham KidsUp Tieng Viet khong phai goi gia han theo chu ky. Chi tiet LH 18001091 (0d) hoac truy cap Digital Market https://dimarket.vn/ – nen tang TMDT cua VNPT. Tran trong! | F16: Pass
A17: IV | B17: Đăng ký trên Website
A18: 10 | B18: Mua sản phầm thành công trên Web | D18: "1. Truy cập website https://dimarket.vn/ 2. Thực hiện mua gói thanh toán qua TKC" | E18: Giao dịch thành công MT1: Quy khach da thanh toan thanh cong goi san pham KidsUp Tieng Viet (Gia cuoc 3000d/ngay, gia han tu dong). De huy, vui long soan HUY PAtest gửi 1376. Truy cap https://dimarket.vn/ de so huu cac san pham voi gia cuoc uu dai chi co tren Digital Market – nen tang TMDT cua VNPT. CSKH 18001091 (0d). Tran trong! MT2: Cam on Quy khach da lua chon KidsUp Tieng Viet - ung dung hoc doc Tieng Viet danh cho tre tu 4 den 8 tuoi. Truy cap https://www.kidsup.net/kidsup-tieng-viet/ de tai ve ung dung va kich hoat License su dung dich vu. Chi tiet lien he 18001091(0d). | F18: Pass
A19: 11 | B19: Mua sản phầm không thành công trên Web do TK không đủ tiền | D19: "1. Truy cập website https://dimarket.vn/ 2. Thực hiện mua gói thanh toán qua TKC" | E19: Giao dich khong thanh cong do thue bao khong du tien trong tai khoan. Vui long nap tien https://my.vnpt.com.vn/adv/nt (TB tra truoc), soan *105*[Mã thẻ]# (TB tra sau) va thu lai hoac thanh toan qua VNPT Pay tai [Link QR Code] (hieu luc 10 phut). CSKH 18001091 (0d). Tran trong! | F19: Pass
A20: V | B20: Các kịch bản MT khác
A21: 12 | B21: Trợ giúp | D21: 1. Soạn TG DM gửi 1376 | E21: "Hệ thống trả MT: Chao mung Quy khach den voi thong tin tro giup dich vu Digital Market – nen tang TMDT cua VNPT. De thanh toan san pham qua tai khoan di dong, soan DK KIDTV gửi 1376. De huy goi san pham gia han qua tai khoan di dong, soan HUY PAtest gửi 1376. Truy cap https://dimarket.vn/ de tim hieu ve ma san pham hoac LH 18001091 (0d). Tran trong! | F21: Pass
A22: 13 | B22: Sai cú pháp | D22: 1. Soạn Abc gửi 1376 | E22: "Hệ thống trả MT: Yeu cau cua Quy khach chua duoc thuc hien do cu phap khong dung. Vui long soan TG DM gui 1376 hoac truy cap https://dimarket.vn/ de duoc tro giup dich vu Digital Market – nen tang TMDT cua VNPT. CSKH 18001091 (0d). Tran trong! | F22: Pass
A23: 14 | B23: Lỗi hệ thống | D23: "1. Thực hiện thao tác khi hệ thống bận Soạn TG DM gửi 1376" | E23: "Hệ thống trả MT: Yeu cau cua Qua khach chua duoc thuc hien do he thong dang ban. Vui long thu lai sau. CSKH 18001091 (0d). Tran trong! | F23: Pass
